Workbook

Sheet 0_README
A1: DAY 22 — CAMPUS 24/7 MONETIZATION MODEL
A2: AI Pricing · GTM · Evidence — AI-IN-ACTION Track 1
A4: QUY ƯỚC MÀU — CHỈ ĐIỀN VÀO Ô MÀU VÀNG
A5: Ô VÀNG, chữ xanh dương | B5: Ô bạn phải điền
A6: Ô XÁM, chữ đen | B6: Công thức tự tính — KHÔNG SỬA
A7: Chữ xanh lá | B7: Link sang tab khác
A8: Ô XÁM đậm nhạt | B8: Bảng tham chiếu, chỉ đọc
A10: THỨ TỰ LÀM — 6 TRẠM, 120 PHÚT
A11: Trạm 1 · 15' | B11: Ngân sách khách & định nghĩa Job → điền S1–S2 của tab 1_Cost_Job
A12: Trạm 2 · 20' | B12: Value Metric → tab 3_Value_Metric
A13: Trạm 3 · 30' | B13: Cost/Job, giá sàn & giá trần → tab 1_Cost_Job (S3–S8) rồi 2_Pricing
A14: Trạm 4 · 20' | B14: Kênh phân phối & Affordability Test → tab 4_Channel_Fit
A15: Trạm 5 · 15' | B15: Pain Moment & 90-Day Plan → tab 5_90Day_Plan
A16: Trạm 6 · 20' | B16: Evidence Pack & ráp One-Pager → tab 5_90Day_Plan + file .docx
A18: 3 QUY TẮC KHÔNG ĐƯỢC PHÁ
A19: 1. Chia cho số job HOÀN THÀNH, không phải số job đã thử.
A20: 2. HITL và Retry không được để 0 nếu không có lý do viết ra được.
A21: 3. Mọi con số giá API phải có NGÀY kiểm tra (xem tab 6_Benchmarks).
A23: Giá tham chiếu trong workbook này được chốt ngày 26/08/2026. Nhiều mức giá là KHUYẾN MẠI CÓ HẠN.
A24: Bạn PHẢI tự mở lại trang giá của nhà cung cấp và cập nhật — đây là một phần của bài tập.
A26: TRẠNG THÁI | B26: Bản mô hình giả định: đang deploy, chưa eval/pilot/khách trả tiền.
A27: Phạm vi job | B27: AI chuẩn bị hồ sơ đạt rubric; cán bộ trường vẫn kiểm tra và quyết định.
A28: Cách đọc | B28: 5 tab làm bài giữ nguyên; tab 7 giải thích mọi input, tab 8 stress test, tab 9 truy vết One-Pager.
A29: HITL | B29: A: trường xử lý nghiệp vụ không đạt; vẫn có QA nội bộ và hỗ trợ kỹ thuật trong COGS.
A30: Công thức đã điều chỉnh | B30: B56 thêm hỗ trợ cố định; pricing B19/B33/sensitivity tính đúng Hybrid. Không thay toàn bộ template.
A31: Giá sàn & GM | B31: So giá hiệu dụng gồm phân bổ phí nền với Cost/Job; usage 0,15 USD riêng không phải giá hiệu dụng 0,275 USD.
A32: Containment | B32: 80% là giả định chất lượng hồ sơ chuẩn bị; KHÔNG phải AI tự giải quyết 80% ticket nghiệp vụ.
A33: Thuế/FX | B33: Tính USD trước thuế; VND chỉ tham khảo. Không thu tiền, liên hệ hay deploy trong bài này.
A34: Bản nháp cá nhân | B34: Hoàng Quốc Dũng cần đọc và diễn đạt quyết định bằng lời của mình; không tuyên bố đã chạy pilot hoặc test người lạ.
A35: Gate trước thu tiền | B35: QA 100% trước pilot; 5% QA chỉ là steady-state sau khi eval + pilot qua gate.
A36: Ngày kiểm tra giá | B36: 08/10/2026
A37: Nguồn tỷ giá | B37: Vietcombank XML, bán USD 26.100 VND; timestamp nguồn 08/10/2026 17:06:38.

Sheet 1_Cost_Job
A1: TAB 1 — COST/JOB CALCULATOR
A2: Trạm 1 (S1–S2) và Trạm 3 (S3–S8). Chỉ điền ô vàng.
A4: S1. ĐỊNH NGHĨA JOB
A5: 1 job của bạn là gì? | B5: 1 hồ sơ AI chuẩn bị đạt rubric: đủ trường bắt buộc, checklist, draft có căn cứ, đúng quyền; không cần nhà cung cấp sửa tay. Cán bộ vẫn review. | D5: Phải là thứ KHÁCH coi là giá trị — không phải '1 request'
A6: Biến thể HITL: A hay B? | B6: A | D6: A = khách tự xử lý ca escalate · B = BẠN chịu (outcome/managed)
A8: S2. KHỐI LƯỢNG
A9: Số job THỬ / tháng | B9: ='7_Assumptions'!B5 -> 1000 | C9: job
A10: Tỷ lệ hồ sơ AI chuẩn bị đạt rubric — GIẢ ĐỊNH | B10: ='7_Assumptions'!B6 -> 0.8 | D10: Chưa đo → ước tính và ghi rõ
A11: → Số hồ sơ đạt rubric / tháng (không phải ticket resolved) | B11: =B9*B10 -> 800 | C11: job | D11: MẪU SỐ của Cost/Job
A12: → Hồ sơ không đạt: trường xử lý thủ công | B12: =B9-B11 -> 200 | C12: job | D12: Số ca phải escalate
A14: S3. API — LLM
A15: Giá input ($ / 1M token) | B15: ='7_Assumptions'!B18 -> 0.15 | D15: GPT-4o mini, trang model chính thức 08/10/2026
A16: Giá output ($ / 1M token) | B16: ='7_Assumptions'!B19 -> 0.6
A17: Giá cache WRITE ($ / 1M token) | B17: 0 | D17: Anthropic 5-phút = 1,25× input
A18: Giá cache READ ($ / 1M token) | B18: ='7_Assumptions'!B20 -> 0.075 | D18: ≈ 0,1× input (giảm 90%)
A19: Số lượt (turns) / job | B19: ='7_Assumptions'!B24 -> 6 | C19: lượt
A20: Token input CACHE ĐƯỢC / lượt | B20: 0 | C20: token | D20: System prompt + KB + few-shot
A21: Token input FRESH / lượt | B21: ='7_Assumptions'!B25 -> 4000 | C21: token | D21: Câu hỏi khách + dữ liệu động
A22: Token output / lượt | B22: ='7_Assumptions'!B26 -> 600 | C22: token
A23: → Cache write / job | B23: =B20*B17/1000000 -> 0
A24: → Cache read / job | B24: =(B19-1)*B20*B18/1000000 -> 0
A25: → Input fresh / job | B25: =B19*B21*B15/1000000 -> 0.0036
A26: → Output / job | B26: =B19*B22*B16/1000000 -> 0.00216
A27: → LLM / job — CÓ prompt caching | B27: =SUM(B23:B26) -> 0.00576
A28: → LLM / job — KHÔNG cache | B28: =B19*(B20+B21)*B15/1000000+B26 -> 0.00576
A29: → % tiết kiệm nhờ caching | B29: =IF(B28=0,0,1-B27/B28) -> 0 | D29: Đòn bẩy rẻ nhất bạn có
A30: Dùng Batch API? (1 = có, 0 = không) | B30: 0 | D30: Batch giảm 50% — chỉ khi job KHÔNG cần realtime
A31: → LLM / job sau Batch | B31: =B27*(1-B30*0.5) -> 0.00576
A33: S4. API — SPEECH (để 0 nếu sản phẩm không có thoại)
A34: Giá STT ($ / phút) | B34: 0 | D34: Deepgram streaming list $0,0077/phút
A35: Số phút audio / job | B35: 0 | C35: phút
A36: Giá TTS ($ / 1M ký tự) | B36: 0 | D36: ElevenLabs Flash $50 · Google Standard $4
A37: Số ký tự TTS / job | B37: 0 | C37: ký tự | D37: ≈ 900 ký tự cho mỗi phút bot nói
A38: → Speech / job | B38: =B34*B35+B36*B37/1000000 -> 0
A40: S5. INFRA
A41: Infra / job ($) | B41: ='7_Assumptions'!B13/B9+'7_Assumptions'!B14+'7_Assumptions'!B16*'7_Assumptions'!B17/1000000 -> 0.03508 | D41: 30 USD cố định / N + 0,005/job + embedding 4.000 token × 0,02/1M
A42: Telephony ($ / phút) | B42: 0
A43: → Infra / job | B43: =B41+B42*B35 -> 0.03508
A45: S6. RETRY
A46: Tỷ lệ job phải chạy lại | B46: ='7_Assumptions'!B27 -> 0.08 | D46: ĐỪNG để 0%. Thực tế 5–10% là bình thường
...

Sheet 2_Pricing
A1: TAB 2 — PRICING SANITY CHECK
A2: Trạm 3. Cost/Job tự lấy từ tab 1. Bạn điền giá bán và các con số neo giá.
A4: GIÁ SÀN
A5: Cost/Job (từ tab 1_Cost_Job) | B5: ='1_Cost_Job'!B66 -> 0.082876 | C5: $/job
A6: Hệ số an toàn tối thiểu | B6: 3 | C6: × | D6: Giá bán ≥ 3 × Cost/Job
A7: → GIÁ SÀN | B7: =B5*B6 -> 0.248628 | C7: $/job
A9: GIÁ TRẦN — NEO THEO THỨ KHÁCH ĐANG CHI
A10: Giá trị khách tiết kiệm được / tháng ($) | B10: ='7_Assumptions'!B22 -> 960 | D10: Neo theo giá trị
A11: Số job / tháng của 1 khách | B11: ='1_Cost_Job'!B11 -> 800 | C11: job
A12: → Trần theo giá trị — mức 10% | B12: =IF(B11=0,0,B10*0.1/B11) -> 0.12 | C12: $/job
A13: → Trần theo giá trị — mức 25% | B13: =IF(B11=0,0,B10*0.25/B11) -> 0.3 | C13: $/job
A14: Lương tương đương tháng — chỉ neo tham khảo, không thay 1 nhân sự | B14: ='7_Assumptions'!B11*'7_Assumptions'!B12 -> 960 | D14: Neo theo nhân công
A15: → Trần theo nhân công — mức 50% | B15: =IF(B11=0,0,B14*0.5/B11) -> 0.6 | C15: $/job
A16: → Trần theo nhân công — mức 70% | B16: =IF(B11=0,0,B14*0.7/B11) -> 0.84 | C16: $/job
A18: GIÁ BÁN CỦA BẠN
A19: ★ Giá hiệu dụng / job đạt (phí nền phân bổ + usage) | B19: ='7_Assumptions'!B8+'7_Assumptions'!B7/B11 -> 0.275 | C19: $/job | D19: Hybrid 100 USD/tháng + 0,15 USD/hồ sơ đạt; ở 800 hồ sơ → 0,275 USD/job. Không phải giá flat outcome.
A20: → Bội số so với Cost/Job | B20: =IF(B5=0,0,B19/B5) -> 3.3182103
A21: → GROSS MARGIN | B21: =IF(B19=0,0,(B19-B5)/B19) -> 0.69863273
A22: → Đèn: bội số ≥ 3? | B22: =IF(B20>=B6,"OK — ĐẠT","KHÔNG ĐẠT — quay lại tab 1") -> OK — ĐẠT
A23: → Đèn: Gross Margin | B23: =IF(B21>=0.6,"OK — AN TOÀN (≥60%)",IF(B21>=0.5,"CẢNH BÁO (50–60%)","NGUY HIỂM (<50%)")) -> OK — AN TOÀN (≥60%)
A24: → Đèn: GM có cao bất thường? | B24: =IF(B21>0.85,"NGHI NGỜ — nhiều khả năng bạn quên một khoản chi phí","OK") -> OK
A25: → Giá bán nằm trong vùng neo? | B25: =IF(AND(B19>=B7,B19<=MAX(B13,B16)),"OK — trong vùng giá bán","XEM LẠI — ngoài vùng giá sàn/trần") -> OK — trong vùng giá bán
A27: BREAKEVEN CONTAINMENT — ngưỡng sống còn
A28: Ký hiệu: v = chi phí biến đổi / job thử · q = QA / job thử · e = chi phí 1 ca escalate
A29: v — chi phí biến đổi / job thử | B29: ='1_Cost_Job'!B31+'1_Cost_Job'!B38+'1_Cost_Job'!B43+'1_Cost_Job'!B47 -> 0.0413008
A30: q — QA nội bộ / job thử | B30: ='1_Cost_Job'!B51*('1_Cost_Job'!B52/60)*'1_Cost_Job'!B50 -> 0.015
A31: e — chi phí 1 ca escalate | B31: =IF('1_Cost_Job'!B6="B",('1_Cost_Job'!B53/60)*'1_Cost_Job'!B50,0) -> 0
A32: Gross Margin mục tiêu | B32: 0.6
A33: ★ Tỷ lệ đạt tối thiểu để GM COGS đạt mục tiêu | B33: =MAX(0,('1_Cost_Job'!B9*(B29+B30+B31)+'1_Cost_Job'!B57-(1-B32)*'7_Assumptions'!B7)/('1_Cost_Job'!B9*((1-B32)*'7_Assumptions'!B8+B31))) -> 0.43834667 | D33: Ngưỡng GM 60%, không phải hòa vốn lợi nhuận ròng. Hybrid F+u×N×R; xem tab 8 và ghi chú công thức.
A34: Tỷ lệ đạt hiện tại — GIẢ ĐỊNH, chưa eval | B34: ='1_Cost_Job'!B10 -> 0.8
A35: → Kết luận | B35: =IF(B34>=B33,"ĐẠT TRONG GIẢ ĐỊNH — cần đo pilot","CHƯA ĐẠT TRONG GIẢ ĐỊNH — sửa mô hình") -> ĐẠT TRONG GIẢ ĐỊNH — cần đo pilot
A37: SENSITIVITY — mô hình gãy ở đâu?
A38: Containment | B38: Cost/Job | C38: Gross Margin | D38: Đánh giá
A39: 0.5 | B39: =($B$29+$B$30+$B$31*(1-A39)+'1_Cost_Job'!$B$57/'1_Cost_Job'!$B$9)/A39 -> 0.1326016 | C39: =1-B39/('7_Assumptions'!$B$8+'7_Assumptions'!$B$7/('1_Cost_Job'!$B$9*A39)) -> 0.62113829 | D39: =IF(C39>=0.6,"An toàn",IF(C39>=0.5,"Cảnh báo","Nguy hiểm")) -> An toàn
A40: 0.6 | B40: =($B$29+$B$30+$B$31*(1-A40)+'1_Cost_Job'!$B$57/'1_Cost_Job'!$B$9)/A40 -> 0.11050133 | C40: =1-B40/('7_Assumptions'!$B$8+'7_Assumptions'!$B$7/('1_Cost_Job'!$B$9*A40)) -> 0.65104842 | D40: =IF(C40>=0.6,"An toàn",IF(C40>=0.5,"Cảnh báo","Nguy hiểm")) -> An toàn
A41: 0.7 | B41: =($B$29+$B$30+$B$31*(1-A41)+'1_Cost_Job'!$B$57/'1_Cost_Job'!$B$9)/A41 -> 0.094715429 | C41: =1-B41/('7_Assumptions'!$B$8+'7_Assumptions'!$B$7/('1_Cost_Job'!$B$9*A41)) -> 0.67658146 | D41: =IF(C41>=0.6,"An toàn",IF(C41>=0.5,"Cảnh báo","Nguy hiểm")) -> An toàn
A42: 0.8 | B42: =($B$29+$B$30+$B$31*(1-A42)+'1_Cost_Job'!$B$57/'1_Cost_Job'!$B$9)/A42 -> 0.082876 | C42: =1-B42/('7_Assumptions'!$B$8+'7_Assumptions'!$B$7/('1_Cost_Job'!$B$9*A42)) -> 0.69863273 | D42: =IF(C42>=0.6,"An toàn",IF(C42>=0.5,"Cảnh báo","Nguy hiểm")) -> An toàn
A43: 0.9 | B43: =($B$29+$B$30+$B$31*(1-A43)+'1_Cost_Job'!$B$57/'1_Cost_Job'!$B$9)/A43 -> 0.073667556 | C43: =1-B43/('7_Assumptions'!$B$8+'7_Assumptions'!$B$7/('1_Cost_Job'!$B$9*A43)) -> 0.71786894 | D43: =IF(C43>=0.6,"An toàn",IF(C43>=0.5,"Cảnh báo","Nguy hiểm")) -> An toàn
A44: 0.95 | B44: =($B$29+$B$30+$B$31*(1-A44)+'1_Cost_Job'!$B$57/'1_Cost_Job'!$B$9)/A44 -> 0.069790316 | C44: =1-B44/('7_Assumptions'!$B$8+'7_Assumptions'!$B$7/('1_Cost_Job'!$B$9*A44)) -> 0.72659464 | D44: =IF(C44>=0.6,"An toàn",IF(C44>=0.5,"Cảnh báo","Nguy hiểm")) -> An toàn
A46: Nhìn cột Gross Margin: mô hình của bạn mong manh đến mức nào khi AI làm sai nhiều hơn dự kiến?
...

Sheet 3_Value_Metric
A1: TAB 3 — VALUE METRIC SCORECARD
A2: Trạm 2. Chấm 0 / 1 / 2 điểm cho mỗi câu, theo THỰC TẾ HÔM NAY.
A4: A. ATTRIBUTION — bạn đo được kết quả là do AI tạo ra không?
A5: 1. Tôi có log đầy đủ mỗi job AI xử lý, gắn được với kết quả cuối cùng | B5: 1
A6: 2. Tôi có bộ eval đo được tỷ lệ AI làm đúng, có số liệu | B6: 0
A7: 3. Khách hàng đồng ý với cách tôi định nghĩa 'thành công' của một job | B7: 0
A8: 4. Tôi phân biệt được kết quả do AI tạo ra với kết quả do yếu tố khác | B8: 1
A9: 5. Tôi viết được định nghĩa chặt như Intercom: cái gì tính tiền, cái gì không | B9: 1
A10: → ĐIỂM ATTRIBUTION (tối đa 10) | B10: =SUM(B5:B9) -> 3
A12: B. AUTONOMY — AI tự chạy hay cần người?
A13: 1. AI hoàn thành job từ đầu đến cuối, không cần người bấm nút giữa chừng | B13: 0
A14: 2. Job chạy được ngoài giờ hành chính mà không ai trực | B14: 1
A15: 3. Khi AI không chắc, nó tự chuyển tiếp đúng chỗ — không cần người phân loại | B15: 1
A16: 4. Tỷ lệ ca phải có người can thiệp dưới 20% | B16: 0
A17: 5. Người vận hành chỉ kiểm tra mẫu (QA), không xử lý từng ca | B17: 0
A18: → ĐIỂM AUTONOMY (tối đa 10) | B18: =SUM(B13:B17) -> 2
A20: GỢI Ý CỦA MODEL
A21: → Value Metric gợi ý | B21: =IF(AND(B10>=7,B18>=7),"OUTCOME",IF(AND(B10>=7,B18<7),"USAGE",IF(AND(B10<7,B18>=7),"USAGE (an toàn)","SEAT hoặc HYBRID"))) -> SEAT hoặc HYBRID
A22: Ngưỡng 7/10 là quy ước của bài tập, không phải chuẩn ngành — dùng để buộc bạn ra quyết định, không phải để thay bạn quyết định.
A24: BENCHMARK NGƯỢC — 2 sản phẩm thật cùng loại job
A25: Tên sản phẩm | B25: Value Metric | C25: Giá công bố | D25: Link nguồn
A26: Freshdesk Freddy AI Copilot | B26: Seat — add-on theo cán bộ | C26: $29/agent/tháng, billed annually; thêm gói Freshdesk đủ điều kiện | D26: https://www.freshworks.com/freshdesk/pricing/
A27: Zendesk Copilot | B27: Seat — add-on theo cán bộ | C27: $50/agent/tháng, paid yearly; chưa gồm Zendesk nền | D27: https://www.zendesk.com/pricing/
A29: QUYẾT ĐỊNH CUỐI
A30: Value Metric tôi chọn | B30: Hybrid: phí nền theo trường + usage hồ sơ chuẩn bị hợp lệ
A31: Nếu KHÁC gợi ý — lý do thị trường là gì? | B31: Khớp gợi ý Seat/Hybrid. Chưa có eval hay khách đồng ý success; cán bộ vẫn phê duyệt nên không chọn Outcome nghiệp vụ.
A32: Decision Note — câu 1: tôi chọn đơn vị nào? | B32: Tôi đề xuất phí nền cho hàng chờ, audit, KB và quyền; usage gắn một hồ sơ chuẩn bị hợp lệ, giới hạn theo revision.
A33: Decision Note — câu 2: bằng chứng Attribution / Autonomy? | B33: Attribution 3/10, Autonomy 2/10 chỉ có thiết kế/demo một phần. Stub chưa chứng minh chất lượng; eval và pilot là gate.
A34: Decision Note — câu 3: mô hình này lỗ trong tình huống nào? | B34: Mô hình gãy nếu phải QA mọi hồ sơ, support tăng hoặc khách không chấp nhận phí nền; không tính stub/timeout/hỏng vào usage.
A36: Giới hạn benchmark | B36: Cùng job hỗ trợ nhân viên tóm tắt/tra cứu/soạn phản hồi; không đặc thù trường đại học, không dùng giá này làm willingness-to-pay.
A37: Ngày kiểm tra giá | B37: 08/10/2026

Sheet 4_Channel_Fit
A1: TAB 4 — CHANNEL FIT & AFFORDABILITY TEST
A2: Trạm 4. Chọn ĐÚNG 1 kênh cho 90 ngày đầu — và chứng minh bằng số.
A4: A. NGÂN SÁCH CAC — bạn nuôi nổi kênh nào?
A5: ARPU / tháng ($) | B5: ='2_Pricing'!B58 -> 220
A6: Gross Margin (từ tab 2_Pricing) | B6: ='2_Pricing'!B21 -> 0.69863273
A7: Phân khúc (SMB / Mid / Enterprise) | B7: SMB | D7: Pilot một đơn vị: dùng payback 12 tháng bảo thủ; không coi cả trường là SMB. Procurement trường có thể dài hơn.
A8: → CAC payback cho phép (tháng) | B8: =IF(B7="SMB",12,IF(B7="Mid",18,24)) -> 12 | C8: tháng | D8: Bessemer, Scaling to $100M (2024)
A9: ★ NGÂN SÁCH CAC / khách | B9: =B5*B6*B8 -> 1844.3904 | D9: ARPU × GM × số tháng payback
A10: → ACV (giá trị hợp đồng / năm) | B10: =B5*12 -> 2640
A12: B. SALES VIABILITY — một AE phải chốt bao nhiêu deal?
A13: Quota / AE / năm ($) | B13: ='7_Assumptions'!B30 -> 500000 | D13: Quota giả định của lab, không phải nhân viên đã tuyển hoặc benchmark hiện tại.
A14: Số ngày làm việc / năm | B14: ='7_Assumptions'!B31 -> 250 | C14: ngày
A15: → Số deal / AE / năm | B15: =IF(B10=0,0,B13/B10) -> 189.39394
A16: ★ Số deal / AE / NGÀY | B16: =IF(B14=0,0,B15/B14) -> 0.75757576 | C16: deal/ngày
A17: → Kết luận Sales-Led | B17: =IF(B16<=1,"KHẢ THI về mặt số học","BẤT KHẢ THI — ACV quá thấp để nuôi sales rep") -> KHẢ THI về mặt số học
A19: C. ĐỐI CHIẾU CAC THỰC TẾ CỦA MOTION CÓ SALES
A20: Cost per opportunity ($) | B20: ='7_Assumptions'!B32*'7_Assumptions'!B33+'7_Assumptions'!B34 -> 100 | D20: Founder: 8h × 10 USD + 20 USD tools/opportunity. Không dùng ICONIQ chưa kiểm chứng.
A21: Win rate | B21: ='7_Assumptions'!B35 -> 0.25
A22: → CAC founder ước tính / khách — CHƯA THỰC ĐO | B22: =B20/B21+'7_Assumptions'!B37 -> 480
A23: ★ Lệch bao nhiêu lần so với ngân sách CAC? | B23: =IF(B9=0,0,B22/B9) -> 0.26024859 | D23: Đây là bằng chứng chọn kênh của bạn
A24: → Kết luận | B24: =IF(B23<=1,"Founder sales khả thi trong giả định, chưa có pipeline",IF(B23<=3,"Cần giảm CAC/tăng giá — chưa khả thi để scale","Không khả thi theo giả định")) -> Founder sales khả thi trong giả định, chưa có pipeline
A26: D. CHẤM ĐIỂM 3 KÊNH (1 = rất kém, 5 = rất tốt)
A27: Tiêu chí | B27: PLG | C27: Sales-Led | D27: Partner-Led
A28: 1. Ngân sách CAC của tôi nuôi nổi kênh này | B28: 3 | C28: 3 | D28: 2
A29: 2. Khách hàng mục tiêu thực sự mua theo cách này | B29: 1 | C29: 4 | D29: 2
A30: 3. Đội hiện tại có năng lực chạy kênh này ngay | B30: 2 | C30: 3 | D30: 1
A31: 4. Tôi tiếp cận được điểm nhúng / partner trong 30 ngày | B31: 2 | C31: 3 | D31: 1
A32: 5. Kênh này đưa tôi đến ĐÚNG Pain Moment | B32: 2 | C32: 4 | D32: 2
A33: 6. Tôi đo được hiệu quả trong vòng 90 ngày | B33: 3 | C33: 3 | D33: 1
A34: → TỔNG ĐIỂM | B34: =SUM(B28:B33) -> 13 | C34: =SUM(C28:C33) -> 20 | D34: =SUM(D28:D33) -> 9
A35: → Kênh điểm cao nhất | B35: =IF(AND(B34>=C34,B34>=D34),"PLG",IF(C34>=D34,"Sales-Led","Partner-Led")) -> Sales-Led
A37: E. CHỐT KÊNH
A38: ★ Kênh tôi chọn cho 90 ngày đầu | B38: Sales-Led — founder-led pilot, không tuyển AE | D38: ĐÚNG 1 kênh. Chọn 2 kênh trở lên bị trừ điểm.
A39: Nếu Partner-Led: TÊN CÔNG TY partner | B39: Không áp dụng: không chọn Partner-Led | D39: 'Các nền tảng trong ngành' = chưa có kênh
A40: Đã nói chuyện với họ chưa? (Rồi / Chưa) | B40: Không áp dụng; chưa có đối tác/đơn vị pilot
A41: Bạn mang lại giá trị gì cho partner? | B41: Không áp dụng; không giả định quan hệ với VinUni hoặc đối tác khác
A42: Nếu rơi vào vùng không khả thi — lối thoát nào? | B42: Giới hạn scope/onboarding; cần đầu mối học vụ + IT, đo willingness-to-pay. Không tuyển AE khi CAC thuê vượt ngân sách. | D42: Giảm giá để tự phục vụ / tăng giá + service / Partner-Led
A44: SO SÁNH SALES THUÊ VÀ FOUNDER — ĐỀU LÀ GIẢ ĐỊNH
A45: CPO sales thuê | B45: ='7_Assumptions'!B41 -> 1000 | C45: USD | D45: 24h × 35 + 160; không benchmark xác nhận
A46: CAC sales thuê gồm onboarding | B46: ='7_Assumptions'!B42 -> 4080 | C46: USD
...

Sheet 5_90Day_Plan
A1: TAB 5 — PAIN MOMENT · 90-DAY PLAN · EVIDENCE PACK
A2: Trạm 5 và Trạm 6.
A4: A. PAIN MOMENT — phải đủ 3 phần
A5: MẤY GIỜ khách đau nhất? | B5: 08:30 sáng — giả thuyết cần phỏng vấn
A6: Lúc đó họ ĐANG LÀM GÌ? | B6: Cán bộ mở hàng chờ, đọc yêu cầu tối hôm trước, kiểm hồ sơ thiếu và soạn phản hồi.
A7: Họ đang DÙNG APP / KÊNH NÀO? | B7: Dashboard học vụ; trước đó yêu cầu vào chat/cổng SV hoặc email. Chưa khảo sát trường thật.
A8: → Điểm nhúng cụ thể của bạn | B8: /dashboard → /tickets/[ticketId] cho cán bộ; /chat cho SV. Nhúng portal trường là kế hoạch, chưa tích hợp. | D8: Một bề mặt tích hợp có tên, không phải 'website của chúng tôi'
A10: B. 90-DAY PLAN
B11: THÁNG 1 — Học | C11: THÁNG 2–3 — Đòn bẩy | D11: THÁNG 4+ — Mở rộng
A12: Kênh sử dụng | B12: Sales-Led — founder discovery/pilot | C12: Cùng Sales-Led — founder | D12: Cùng kênh nếu qua gate; roadmap ngoài 90 ngày
A13: Mục tiêu số khách | B13: 0 khách trả tiền; mục tiêu 1 đơn vị đồng ý pilot | C13: Mục tiêu 1 pilot, 2 trường trả tiền đến 06/01/2027; hiện 0 | D13: Mục tiêu 5 trường đến 06/04/2027, có điều kiện; hiện 0
A14: Việc cụ thể 1 | B14: Phỏng vấn 5 cán bộ + 2 đầu mối IT/ngân sách trước 22/10/2026; chưa liên hệ. | C14: Pilot 4 tuần với 3 cán bộ và ≥100 hồ sơ; QA toàn bộ trước khi chuyển sang lấy mẫu. | D14: Chỉ mở rộng sau pilot có trả tiền; chuẩn hóa triển khai KB, phân quyền, xuất dữ liệu.
A15: Việc cụ thể 2 | B15: Nối AI thật, log token/time; chấm 50 case hồ sơ + 15 case safety, QA 100%; deadline 22/10/2026. | C15: Đo baseline và review phút/job, lỗi nguồn, usage billing; báo cáo trước 06/12/2026. | D15: Chuẩn hóa onboarding ≤8h/trường; stress volume/QA/support trước mỗi gói.
A16: Việc cụ thể 3 | B16: Chốt scope/consent pilot 1 đơn vị trước 07/11/2026; chưa có đơn vị nhận thử. | C16: Thử gói 100 USD nền + 0,15 USD/job với 2 trường; dừng nếu giá trị, CAC hoặc chất lượng không đạt. | D16: Không mở kênh thứ hai trong 90 ngày; chỉ cân nhắc AE khi CAC thuê nằm trong trần.
A17: KPI đo được | B17: Gate: ≥40/50 hồ sơ đạt; 15/15 case safety đúng; 0 ghi nghiệp vụ ngoài quyền. Mục tiêu chưa đo. | C17: Mục tiêu: đạt ≥80%, giảm thời gian ≥30%, GM COGS ≥60%, CAC ≤trần tab4; chưa có kết quả. | D17: Mục tiêu 5 trường; GM ≥60%, QA cost không vượt mô hình, 0 lỗi quyền nghiêm trọng.
A18: Người chịu trách nhiệm | B18: Hoàng Quốc Dũng — người phụ trách đề xuất cho bài cá nhân | C18: Hoàng Quốc Dũng; cán bộ/IT pilot chưa xác định, cần đồng thuận | D18: Hoàng Quốc Dũng — đầu mối đề xuất; phối hợp nhóm khi được thống nhất
A19: Tháng 1 là giai đoạn HỌC, không phải scale. Kế hoạch 'tháng 1 lấy 200 khách ở 5 ngành' là kế hoạch chưa ai từng thử làm.
A21: C. EVIDENCE PACK — 3 tài sản bán hàng
A22: Tài sản | B22: Đã có? (Rồi/Chưa) | C22: Nội dung 1 câu — hoặc việc cần làm | D22: Người phụ trách · Deadline
A23: 1. Eval Results | B23: Chưa có kết quả thực đo | C23: Chuẩn bị rubric 50 hồ sơ + 15 safety, log model/token/revision; mục tiêu 40/50 và 15/15. | D23: Hoàng Quốc Dũng · 22/10/2026
A24: 2. Risk Checklist | B24: Có bản nháp Q&A; chưa IT duyệt | C24: docs/Evidence_Pack.md: hallucination/HITL, API data/retention, quyền/xuất dữ liệu/exit; chưa chứng nhận. | D24: Hoàng Quốc Dũng · 29/10/2026
A25: 3. Pilot Report | B25: Chưa có pilot | C25: Tìm 1 đơn vị; mục tiêu 4 tuần, 3 cán bộ, ≥100 hồ sơ; baseline/assisted time, chất lượng và cost. | D25: Hoàng Quốc Dũng · 06/12/2026 (phụ thuộc đơn vị đồng ý)
A26: Ô nào CHƯA CÓ thì ghi deadline — đừng bỏ trống. Thành thật về khoảng trống được điểm cao hơn bịa nội dung.
A28: D. BÀI TEST NGƯỜI LẠ — nhóm khác đọc One-Pager trong 2 phút
A29: Họ trả lời được: bán gì, cho ai, tính tiền theo đơn vị nào? (Được/Không) | B29: Chưa test người lạ; có định vị/job/metric rõ trong One-Pager. Deadline 22/10/2026.
A30: Họ trả lời được: có lãi trên mỗi đơn vị không, số nào chứng minh? (Được/Không) | B30: Tự kiểm số học đã làm; người lạ chưa đọc. Deadline 22/10/2026.
A31: Họ trả lời được: tiếp cận khách qua đâu, vì sao kênh đó? (Được/Không) | B31: Kênh + lý do đã viết; chưa test với người lạ. Deadline 22/10/2026.
A32: Số câu họ phải hỏi lại (mục tiêu ≤ 3) | B32: Chưa đo; mục tiêu ≤3 câu hỏi lại. Không ghi 0 giả.
A34: Deadline kết thúc 90 ngày | B34: ='7_Assumptions'!B56 -> 06/01/2027
A35: Tiêu chí dừng | B35: Không có đơn vị đồng ý thử → báo cáo discovery, không bịa pilot. Chưa qua gate → tiếp tục QA 100%, chưa bán gói steady-state.

Sheet 6_Benchmarks
A1: DAY22 — NGUỒN GIÁ ĐÃ KIỂM TRA CHO CAMPUS 24/7
A2: Phạm vi | B2: Chỉ các nguồn dùng trong bài; không chứng thực bảng giá cũ của template.
A3: NGÀY KIỂM TRA | B3: 08/10/2026
A4: Chính sách | B4: USD trước thuế; không giả định giảm giá/caching; ghi rõ add-on và chu kỳ trả tiền.
A5: Nhóm | B5: Mục | C5: Giá | D5: Đơn vị | E5: Nguồn / lưu ý
A6: LLM | B6: GPT-4o mini — input | C6: 0.15 | D6: USD / 1M token | E6: https://developers.openai.com/api/docs/models/gpt-4o-mini
A7: LLM | B7: GPT-4o mini — output | C7: 0.6 | D7: USD / 1M token | E7: https://developers.openai.com/api/docs/models/gpt-4o-mini
A8: LLM | B8: GPT-4o mini — cached input | C8: 0.075 | D8: USD / 1M token | E8: https://developers.openai.com/api/docs/models/gpt-4o-mini — base case cache token = 0
A9: Embedding | B9: text-embedding-3-small | C9: 0.02 | D9: USD / 1M token | E9: https://developers.openai.com/api/docs/models/text-embedding-3-small
A10: Sản phẩm | B10: Freshdesk Freddy AI Copilot | C10: 29 | D10: USD / agent / tháng, trả năm | E10: https://www.freshworks.com/freshdesk/pricing/ — add-on Pro/Enterprise, chưa gồm gói nền; tóm tắt và hỗ trợ phản hồi
A11: Sản phẩm | B11: Zendesk Copilot | C11: 50 | D11: USD / agent / tháng, trả năm | E11: https://www.zendesk.com/pricing/ — add-on, chưa gồm Zendesk nền; triage, draft, summaries
A12: Data | B12: OpenAI API | C12: Không train mặc định; abuse logs thường tối đa 30 ngày | D12: Chính sách, không bảo đảm ZDR | E12: https://developers.openai.com/api/docs/guides/your-data — opt-in và ngoại lệ theo endpoint/account
A13: FX | B13: USD bán Vietcombank | C13: 26100 | D13: VND / USD | E13: https://portal.vietcombank.com.vn/Usercontrols/TVPortal.TyGia/pXML.aspx?b=10 — timestamp 08/10/2026 17:06:38
A14: GTM | B14: Payback 12 tháng | C14: Quy ước bài lab | D14: Giả định bảo thủ | E14: HD_Lab22.md §4.4; không coi là benchmark đã kiểm chứng mới.
A15: GTM | B15: CPO founder / AE | C15: 100 / 1.000 | D15: USD / opportunity — giả định | E15: 7_Assumptions!B32:B41; không gắn nhãn số liệu thị trường.
A16: Nguồn dự án | B16: Officer Copilot | C16: AI chuẩn bị; cán bộ quyết định | D16: Phạm vi sản phẩm | E16: C:/Users/dungh/Downloads/Prj_Vinuni/P-120/plan2-3-4.md
A17: Nguồn thực trạng | B17: Runtime stub | C17: StubAgent / StubRag | D17: Chưa đo AI E2E | E17: C:/Users/dungh/Downloads/Prj_Vinuni/P-120/backend/src/campus247/services/runtime.py
A18: Nguồn thực trạng | B18: Eval | C18: Chưa có Actual / N/A | D18: Chưa có số đo | E18: C:/Users/dungh/Downloads/Prj_Vinuni/P-120/eval/results/report.md; C:/Users/dungh/Downloads/Prj_Vinuni/P-120/RAG/group_project/evaluation/RESULT.md

Sheet 7_Assumptions
A1: CAMPUS 24/7 — GIẢ ĐỊNH, KHÔNG PHẢI KẾT QUẢ THỰC ĐO
A2: Ngày lập | B2: 08/10/2026 | C2: Ngày do người dùng cung cấp; kiểm tra nguồn giá cùng ngày.
A3: Trạng thái | B3: Prototype đang deploy; chưa eval, chưa pilot, chưa người dùng | C3: Người dùng xác nhận trong hội thoại.
A4: Quy mô | B4: 1 đơn vị học vụ / 1 trường; chưa có khách trả tiền | C4: Mô hình cho một tài khoản khách hàng, không phải doanh thu hiện có.
A5: Số job thử/tháng | B5: 1000 | C5: Giả định công suất: 50 hồ sơ/ngày × 20 ngày. Chưa đo nhu cầu.
A6: Containment chuẩn bị hồ sơ | B6: 0.8 | C6: Giả định 800/1.000 hồ sơ đạt rubric không cần nhóm cung cấp sửa tay; cán bộ trường vẫn review 100%. Không lấy KPI 70% RAG làm containment.
A7: Phí nền / trường / tháng (USD) | B7: 100 | C7: Giả thuyết giá cho hàng chờ, phân quyền, audit, xuất dữ liệu và vận hành KB; không bao gồm tích hợp hệ thống trường thật.
A8: Phí usage / hồ sơ đạt (USD) | B8: 0.15 | C8: Usage = gói chuẩn bị hồ sơ hợp lệ; không bán kết quả cấp giấy/giải quyết khiếu nại. Không tính tiền timeout, stub, lỗi hoặc bản lặp cùng revision.
A9: Phút cán bộ xử lý trước AI | B9: 15 | C9: Giả định cho đọc hội thoại, kiểm tra thiếu, tra quy định, soạn phản hồi; cần time study, không phải đo thực tế.
A10: Phút cán bộ review sau AI | B10: 3 | C10: Giả định lạc quan cần kiểm chứng. Chỉ tính tiết kiệm cho job đạt; không giảm thời gian xử lý các job không đạt.
A11: Chi phí giờ cán bộ / QA (USD) | B11: 6 | C11: Giả định fully-loaded phục vụ mô hình, không phải mức lương khảo sát.
A12: Giờ làm việc/tháng | B12: 160 | C12: 20 ngày × 8 giờ; dùng neo nhân công, không tuyên bố thay một nhân sự.
A13: Hạ tầng cố định / tháng (USD) | B13: 30 | C13: Ngân sách giả định cho app, PostgreSQL, Chroma, backup; chưa mua gói hoặc có hóa đơn.
A14: Hạ tầng biến đổi / job thử (USD) | B14: 0.005 | C14: Dự phòng truy vấn DB, lưu vết, storage và network; không cộng lặp khoản hạ tầng cố định.
A15: Hỗ trợ kỹ thuật nội bộ / tháng (USD) | B15: 10 | C15: 1 giờ × 10 USD/giờ. COGS trực tiếp, tách khỏi R&D. Cần đo; stress test tăng gấp đôi.
A16: Embedding token phân bổ / job thử | B16: 4000 | C16: 2.000 token embedding truy vấn + 2.000 token phân bổ ingestion. Giả định, cần usage log.
... A20: Giá cached input / 1M token | B20: 0.075 | C20: Nguồn chính thức; base case không hưởng caching. Không áp dụng cache write riêng của Anthropic.
A21: Phút tiết kiệm / job đạt | B21: =B9-B10 -> 12 | C21: Chỉ là capacity released; chưa chứng minh giảm tiền lương thực chi.
A22: Giá trị thời gian / tháng (USD) | B22: ='1_Cost_Job'!B11*B21/60*B11 -> 960 | C22: Không tính job không đạt là tiết kiệm; không cộng tiết kiệm ngoài giờ sinh viên.
A23: R&D + sales vận hành phân bổ / tháng | B23: 40 | C23: 4 giờ × 10 USD; phân bổ giả định một tài khoản ở trạng thái ổn định. Không gồm CAC/onboarding đầu kỳ; không phản ánh tổng burn startup.
A24: Lượt LLM / job thử | B24: 6 | C24: Budget: safety/intake, hỏi bổ sung, triage, evidence, dossier/draft, quality. Chưa tích hợp thật hoặc đo trace.
A25: Token input fresh / lượt | B25: 4000 | C25: Budget gồm SOP, hội thoại và nguồn truy xuất; chưa đo, không cộng thêm token cache.
A26: Token output / lượt | B26: 600 | C26: Budget schema/intake/checklist/draft; chưa đo.
A27: Retry / job thử | B27: 0.08 | C27: Giả định 8% thêm một lần chạy lại LLM; không phải số đo, không retry vô hạn.
A28: Tỷ lệ QA nội bộ mẫu | B28: 0.05 | C28: 5% chỉ là kịch bản vận hành sau khi qua gate chất lượng. Trước pilot phải QA 100%, xem stress test.
A29: Phút QA / hồ sơ mẫu | B29: 3 | C29: Kiểm thông tin, nguồn, checklist, draft; giả định cần đo.
A30: Quota AE / năm (USD) | B30: 500000 | C30: Giữ giả định bài lab để minh họa affordability, không phải quota nhân viên đã tuyển.
A31: Ngày làm việc / năm | B31: 250 | C31: Giả định bài lab, kiểm tra số học AE; không chứng minh sales trường học khả thi.
A32: Giờ founder / opportunity | B32: 8 | C32: 2h tìm đầu mối + 2h discovery + 2h demo + 2h follow-up. Giá thời gian không bằng 0.
A33: Giá giờ founder (USD) | B33: 10 | C33: Opportunity cost giả định; cần log thời gian thực.
A34: Tools / opportunity (USD) | B34: 20 | C34: Ngân sách giả định cho demo, đi lại và công cụ, cần kiểm bằng chi tiêu.
... A36: Giờ onboarding / khách | B36: 8 | C36: Giới hạn cấu hình KB + đào tạo trong phạm vi demo, không tích hợp SIS/SSO thật.
A37: Onboarding CAC / khách | B37: =B36*B33 -> 80 | C37: 8h × 10 USD; chi phí thu hút/kích hoạt ban đầu, không cộng lặp COGS hàng tháng.
A38: Giờ AE / opportunity | B38: 24 | C38: Kịch bản sales thuê: discovery, demo, hồ sơ IT/procurement, follow-up; chưa khảo sát.
A39: Giá giờ AE fully-loaded (USD) | B39: 35 | C39: Giả định để so với founder; không gắn nhãn benchmark thị trường.
A40: Tools AE / opportunity (USD) | B40: 160 | C40: Giả định chi phí CRM, lead, đi lại phân bổ.
A41: Cost / opportunity AE (USD) | B41: =B38*B39+B40 -> 1000 | C41: Mô hình 24h × 35 + 160, không dùng số ICONIQ chưa xác minh.
A42: CAC AE / khách (USD) | B42: =B41/B35+B37 -> 4080 | C42: Có onboarding cùng cách tính như founder.
A43: Người phụ trách đề xuất | B43: Hoàng Quốc Dũng | C43: Kế hoạch cá nhân cho bài Day22; không giao việc hoặc tuyên bố đồng đội đã nhận.
A44: Thời điểm cán bộ gặp pain | B44: 08:30 sáng ngày làm việc | C44: Giả thuyết: mở dashboard và xử lý tồn đọng yêu cầu tối hôm trước; chưa phỏng vấn.
...

Sheet 8_Stress_Test
A1: STRESS TEST — HYBRID F + u × N × R; KHÔNG GIỮ GIÁ HIỆU DỤNG CỐ ĐỊNH
A2: Mọi kịch bản là giả định; GM chỉ COGS, biên sau overhead là chỉ số quản trị.
A4: Kịch bản | B4: Job thử N | C4: Tỷ lệ đạt R | D4: QA % | E4: Retry % | F4: Support USD | G4: Hệ số API | H4: Infra cố định USD | I4: Job đạt | J4: Doanh thu USD | K4: COGS USD | L4: Cost/job USD | M4: GM COGS | N4: Biên sau overhead | O4: Giá hiệu dụng | P4: Bội giá/cost
A5: Base case | B5: 1000 | C5: 0.8 | D5: 0.05 | E5: 0.08 | F5: 10 | G5: 1 | H5: 30 | I5: =B5*C5 -> 800 | J5: ='7_Assumptions'!$B$7+'7_Assumptions'!$B$8*I5 -> 220 | K5: =B5*('1_Cost_Job'!$B$31*G5*(1+E5)+'7_Assumptions'!$B$14+'7_Assumptions'!$B$16*'7_Assumptions'!$B$17/1000000+D5*'7_Assumptions'!$B$29/60*'7_Assumptions'!$B$11)+H5+F5 -> 66.3008 | L5: =K5/I5 -> 0.082876 | M5: =1-K5/J5 -> 0.69863273 | N5: =1-(K5+'7_Assumptions'!$B$23)/J5 -> 0.51681455 | O5: =J5/I5 -> 0.275 | P5: =J5/K5 -> 3.3182103
A6: Tỷ lệ đạt còn 50% | B6: 1000 | C6: 0.5 | D6: 0.05 | E6: 0.08 | F6: 10 | G6: 1 | H6: 30 | I6: =B6*C6 -> 500 | J6: ='7_Assumptions'!$B$7+'7_Assumptions'!$B$8*I6 -> 175 | K6: =B6*('1_Cost_Job'!$B$31*G6*(1+E6)+'7_Assumptions'!$B$14+'7_Assumptions'!$B$16*'7_Assumptions'!$B$17/1000000+D6*'7_Assumptions'!$B$29/60*'7_Assumptions'!$B$11)+H6+F6 -> 66.3008 | L6: =K6/I6 -> 0.1326016 | M6: =1-K6/J6 -> 0.62113829 | N6: =1-(K6+'7_Assumptions'!$B$23)/J6 -> 0.39256686 | O6: =J6/I6 -> 0.35 | P6: =J6/K6 -> 2.6394855
A7: Tỷ lệ đạt còn 20% | B7: 1000 | C7: 0.2 | D7: 0.05 | E7: 0.08 | F7: 10 | G7: 1 | H7: 30 | I7: =B7*C7 -> 200 | J7: ='7_Assumptions'!$B$7+'7_Assumptions'!$B$8*I7 -> 130 | K7: =B7*('1_Cost_Job'!$B$31*G7*(1+E7)+'7_Assumptions'!$B$14+'7_Assumptions'!$B$16*'7_Assumptions'!$B$17/1000000+D7*'7_Assumptions'!$B$29/60*'7_Assumptions'!$B$11)+H7+F7 -> 66.3008 | L7: =K7/I7 -> 0.331504 | M7: =1-K7/J7 -> 0.48999385 | N7: =1-(K7+'7_Assumptions'!$B$23)/J7 -> 0.18230154 | O7: =J7/I7 -> 0.65 | P7: =J7/K7 -> 1.9607607
A8: QA 20% | B8: 1000 | C8: 0.8 | D8: 0.2 | E8: 0.08 | F8: 10 | G8: 1 | H8: 30 | I8: =B8*C8 -> 800 | J8: ='7_Assumptions'!$B$7+'7_Assumptions'!$B$8*I8 -> 220 | K8: =B8*('1_Cost_Job'!$B$31*G8*(1+E8)+'7_Assumptions'!$B$14+'7_Assumptions'!$B$16*'7_Assumptions'!$B$17/1000000+D8*'7_Assumptions'!$B$29/60*'7_Assumptions'!$B$11)+H8+F8 -> 111.3008 | L8: =K8/I8 -> 0.139126 | M8: =1-K8/J8 -> 0.49408727 | N8: =1-(K8+'7_Assumptions'!$B$23)/J8 -> 0.31226909 | O8: =J8/I8 -> 0.275 | P8: =J8/K8 -> 1.9766255
A9: QA 100% trước pilot | B9: 1000 | C9: 0.8 | D9: 1 | E9: 0.08 | F9: 10 | G9: 1 | H9: 30 | I9: =B9*C9 -> 800 | J9: ='7_Assumptions'!$B$7+'7_Assumptions'!$B$8*I9 -> 220 | K9: =B9*('1_Cost_Job'!$B$31*G9*(1+E9)+'7_Assumptions'!$B$14+'7_Assumptions'!$B$16*'7_Assumptions'!$B$17/1000000+D9*'7_Assumptions'!$B$29/60*'7_Assumptions'!$B$11)+H9+F9 -> 351.3008 | L9: =K9/I9 -> 0.439126 | M9: =1-K9/J9 -> -0.59682182 | N9: =1-(K9+'7_Assumptions'!$B$23)/J9 -> -0.77864 | O9: =J9/I9 -> 0.275 | P9: =J9/K9 -> 0.62624395
A10: API ×2; không giá khuyến mại | B10: 1000 | C10: 0.8 | D10: 0.05 | E10: 0.08 | F10: 10 | G10: 2 | H10: 30 | I10: =B10*C10 -> 800 | J10: ='7_Assumptions'!$B$7+'7_Assumptions'!$B$8*I10 -> 220 | K10: =B10*('1_Cost_Job'!$B$31*G10*(1+E10)+'7_Assumptions'!$B$14+'7_Assumptions'!$B$16*'7_Assumptions'!$B$17/1000000+D10*'7_Assumptions'!$B$29/60*'7_Assumptions'!$B$11)+H10+F10 -> 72.5216 | L10: =K10/I10 -> 0.090652 | M10: =1-K10/J10 -> 0.67035636 | N10: =1-(K10+'7_Assumptions'!$B$23)/J10 -> 0.48853818 | O10: =J10/I10 -> 0.275 | P10: =J10/K10 -> 3.033579
A11: Retry 20% | B11: 1000 | C11: 0.8 | D11: 0.05 | E11: 0.2 | F11: 10 | G11: 1 | H11: 30 | I11: =B11*C11 -> 800 | J11: ='7_Assumptions'!$B$7+'7_Assumptions'!$B$8*I11 -> 220 | K11: =B11*('1_Cost_Job'!$B$31*G11*(1+E11)+'7_Assumptions'!$B$14+'7_Assumptions'!$B$16*'7_Assumptions'!$B$17/1000000+D11*'7_Assumptions'!$B$29/60*'7_Assumptions'!$B$11)+H11+F11 -> 66.992 | L11: =K11/I11 -> 0.08374 | M11: =1-K11/J11 -> 0.69549091 | N11: =1-(K11+'7_Assumptions'!$B$23)/J11 -> 0.51367273 | O11: =J11/I11 -> 0.275 | P11: =J11/K11 -> 3.2839742
A12: Support ×2 | B12: 1000 | C12: 0.8 | D12: 0.05 | E12: 0.08 | F12: 20 | G12: 1 | H12: 30 | I12: =B12*C12 -> 800 | J12: ='7_Assumptions'!$B$7+'7_Assumptions'!$B$8*I12 -> 220 | K12: =B12*('1_Cost_Job'!$B$31*G12*(1+E12)+'7_Assumptions'!$B$14+'7_Assumptions'!$B$16*'7_Assumptions'!$B$17/1000000+D12*'7_Assumptions'!$B$29/60*'7_Assumptions'!$B$11)+H12+F12 -> 76.3008 | L12: =K12/I12 -> 0.095376 | M12: =1-K12/J12 -> 0.65317818 | N12: =1-(K12+'7_Assumptions'!$B$23)/J12 -> 0.47136 | O12: =J12/I12 -> 0.275 | P12: =J12/K12 -> 2.8833249
A13: Volume 500; giữ infra cố định | B13: 500 | C13: 0.8 | D13: 0.05 | E13: 0.08 | F13: 10 | G13: 1 | H13: 30 | I13: =B13*C13 -> 400 | J13: ='7_Assumptions'!$B$7+'7_Assumptions'!$B$8*I13 -> 160 | K13: =B13*('1_Cost_Job'!$B$31*G13*(1+E13)+'7_Assumptions'!$B$14+'7_Assumptions'!$B$16*'7_Assumptions'!$B$17/1000000+D13*'7_Assumptions'!$B$29/60*'7_Assumptions'!$B$11)+H13+F13 -> 53.1504 | L13: =K13/I13 -> 0.132876 | M13: =1-K13/J13 -> 0.66781 | N13: =1-(K13+'7_Assumptions'!$B$23)/J13 -> 0.41781 | O13: =J13/I13 -> 0.4 | P13: =J13/K13 -> 3.0103254
A14: Volume 2.000; nâng infra lên 60 | B14: 2000 | C14: 0.8 | D14: 0.05 | E14: 0.08 | F14: 10 | G14: 1 | H14: 60 | I14: =B14*C14 -> 1600 | J14: ='7_Assumptions'!$B$7+'7_Assumptions'!$B$8*I14 -> 340 | K14: =B14*('1_Cost_Job'!$B$31*G14*(1+E14)+'7_Assumptions'!$B$14+'7_Assumptions'!$B$16*'7_Assumptions'!$B$17/1000000+D14*'7_Assumptions'!$B$29/60*'7_Assumptions'!$B$11)+H14+F14 -> 122.6016 | L14: =K14/I14 -> 0.076626 | M14: =1-K14/J14 -> 0.63940706 | N14: =1-(K14+'7_Assumptions'!$B$23)/J14 -> 0.52176 | O14: =J14/I14 -> 0.2125 | P14: =J14/K14 -> 2.7732101
A15: Pilot miễn phí 100 job / QA 100% | B15: 100 | C15: 0.8 | D15: 1 | E15: 0.08 | F15: 10 | G15: 1 | H15: 30 | I15: =B15*C15 -> 80 | J15: =0 -> 0 | K15: =B15*('1_Cost_Job'!$B$31*G15*(1+E15)+'7_Assumptions'!$B$14+'7_Assumptions'!$B$16*'7_Assumptions'!$B$17/1000000+D15*'7_Assumptions'!$B$29/60*'7_Assumptions'!$B$11)+H15+F15 -> 71.13008 | L15: =K15/I15 -> 0.889126 | M15: N/A — không doanh thu | N15: N/A — không doanh thu | O15: =J15/I15 -> 0 | P15: =J15/K15 -> 0
A16: Giá trị tiết kiệm chỉ 6 phút | B16: 1000 | C16: 0.8 | D16: 0.05 | E16: 0.08 | F16: 10 | G16: 1 | H16: 30 | I16: =B16*C16 -> 800 | J16: ='7_Assumptions'!$B$7+'7_Assumptions'!$B$8*I16 -> 220 | K16: =B16*('1_Cost_Job'!$B$31*G16*(1+E16)+'7_Assumptions'!$B$14+'7_Assumptions'!$B$16*'7_Assumptions'!$B$17/1000000+D16*'7_Assumptions'!$B$29/60*'7_Assumptions'!$B$11)+H16+F16 -> 66.3008 | L16: =K16/I16 -> 0.082876 | M16: =1-K16/J16 -> 0.69863273 | N16: =1-(K16+'7_Assumptions'!$B$23)/J16 -> 0.51681455 | O16: =J16/I16 -> 0.275 | P16: =J16/K16 -> 3.3182103
A18: NGƯỠNG / BIẾN SỐ | B18: Giá trị | C18: Giải thích
A19: R để GM COGS ≥60% | B19: ='2_Pricing'!B33 -> 0.43834667 | C19: Đổi R làm đổi cả số job đạt và giá hiệu dụng; tính trên revenue Hybrid thực.
A20: R để GM COGS ≥50% | B20: ='2_Pricing'!B64 -> 0.217344 | C20: Không phải ngưỡng chất lượng chấp nhận được để triển khai.
A21: R để hòa vốn sau overhead | B21: ='2_Pricing'!B65 -> 0.042005333 | C21: Không bao gồm thu hồi CAC hoặc toàn bộ R&D startup.
A22: QA tối đa để GM COGS ≥60% | B22: =(0.4*'2_Pricing'!B58-('1_Cost_Job'!B62+'1_Cost_Job'!B57))/('1_Cost_Job'!B9*'1_Cost_Job'!B52/60*'1_Cost_Job'!B50) -> 0.12233067 | C22: Giữ tất cả biến còn lại ở base case.
A23: QA tối đa để GM COGS ≥50% | B23: =(0.5*'2_Pricing'!B58-('1_Cost_Job'!B62+'1_Cost_Job'!B57))/('1_Cost_Job'!B9*'1_Cost_Job'!B52/60*'1_Cost_Job'!B50) -> 0.195664 | C23: Nếu QA vượt ngưỡng này thì GM dưới 50%.
A24: Tiết kiệm phút tối thiểu với capture 25% | B24: ='2_Pricing'!B58/('7_Assumptions'!B64*'1_Cost_Job'!B11*'7_Assumptions'!B11/60) -> 11 | C24: WTP chưa đo. Nếu tiết kiệm <11 phút/job, gói 220 USD vượt capture 25%.
A25: Giá trị nếu chỉ tiết kiệm 6 phút | B25: ='1_Cost_Job'!B11*6/60*'7_Assumptions'!B11 -> 480 | C25: Không sửa giả định ROI để làm số đẹp; cần đo bằng time study.
A26: Trần 25% khi chỉ tiết kiệm 6 phút | B26: =B25*0.25 -> 120 | C26: Khi đó gói base case vượt trần giá trị dù GM nhà cung cấp vẫn tốt.
A27: Hạ tầng tăng ở volume lớn | B27: Ngoài gói base | C27: Scenario row14 nâng fixed infra từ 30 lên 60. Không ngoại suy hạ tầng 30 USD cho mọi volume. Gói base tối đa 1.000 job thử.
A28: Pilot không tính là doanh thu | B28: Không doanh thu | C28: Row15 là ngân sách thử nghiệm, không dùng để báo GM. Cần tài trợ chi phí pilot trong R&D; không tuyên bố 5% QA ngay từ prototype.

Sheet 9_OnePager_Trace
A1: TRUY VẾT SỐ ONE-PAGER — ĐƠN VỊ USD, CHƯA PHẢI TRACTION
A2: Chỉ số | B2: Giá trị / công thức | C2: Ô nguồn / loại số
A3: Cost/Job | B3: ='1_Cost_Job'!B66 -> 0.082876 | C3: 1_Cost_Job!B66; tính từ giả định
A4: Giá sàn 3× | B4: ='2_Pricing'!B7 -> 0.248628 | C4: 2_Pricing!B7
A5: Giá hiệu dụng | B5: ='2_Pricing'!B19 -> 0.275 | C5: 2_Pricing!B19, gồm phân bổ phí nền
A6: GM COGS | B6: ='2_Pricing'!B21 -> 0.69863273 | C6: 2_Pricing!B21
A7: Rmin GM 60% | B7: ='2_Pricing'!B33 -> 0.43834667 | C7: 2_Pricing!B33
A8: R giả định | B8: ='1_Cost_Job'!B10 -> 0.8 | C8: 1_Cost_Job!B10; KHÔNG đo
A9: ARPU | B9: ='4_Channel_Fit'!B5 -> 220 | C9: 4_Channel_Fit!B5; không phải doanh thu hiện có
A10: CAC budget | B10: ='4_Channel_Fit'!B9 -> 1844.3904 | C10: 4_Channel_Fit!B9
A11: Deal/AE/ngày | B11: ='4_Channel_Fit'!B16 -> 0.75757576 | C11: 4_Channel_Fit!B16
A12: CAC founder | B12: ='4_Channel_Fit'!B22 -> 480 | C12: 4_Channel_Fit!B22; chưa thực đo
A13: CAC founder/budget | B13: ='4_Channel_Fit'!B23 -> 0.26024859 | C13: 4_Channel_Fit!B23
A14: CAC sales thuê | B14: ='4_Channel_Fit'!B46 -> 4080 | C14: 4_Channel_Fit!B46; giả định
A15: Sales thuê/budget | B15: ='4_Channel_Fit'!B47 -> 2.212113 | C15: 4_Channel_Fit!B47
A16: Biên sau overhead | B16: ='2_Pricing'!B61 -> 0.51681455 | C16: 2_Pricing!B61; không gọi GM
A17: Giá trị thời gian | B17: ='7_Assumptions'!B22 -> 960 | C17: 7_Assumptions!B22; chưa đo/cắt giảm lương
A18: QA ngưỡng GM50% | B18: ='8_Stress_Test'!B23 -> 0.195664 | C18: 8_Stress_Test!B23
A19: Nguồn giá 08/10/2026 | B19: 08/10/2026 | C19: 6_Benchmarks!B3
A20: Phí nền | B20: ='7_Assumptions'!B7 -> 100 | C20: 7_Assumptions!B7
A21: Phí usage | B21: ='7_Assumptions'!B8 -> 0.15 | C21: 7_Assumptions!B8
A22: Khối lượng thử | B22: ='1_Cost_Job'!B9 -> 1000 | C22: 1_Cost_Job!B9
A23: Job đạt | B23: ='1_Cost_Job'!B11 -> 800 | C23: 1_Cost_Job!B11
A24: Attribution | B24: ='3_Value_Metric'!B10 -> 3 | C24: 3_Value_Metric!B10, score thực trạng thiết kế/demo
A25: Autonomy | B25: ='3_Value_Metric'!B18 -> 2 | C25: 3_Value_Metric!B18, không có chất lượng AI thật
A26: Freshdesk add-on | B26: 29 | C26: 6_Benchmarks!C10, nguồn chính thức
A27: Zendesk add-on | B27: 50 | C27: 6_Benchmarks!C11, nguồn chính thức
A28: Tiết kiệm phút/job | B28: ='7_Assumptions'!B21 -> 12 | C28: 7_Assumptions!B21, giả định
A29: Pilot job mục tiêu | B29: ='7_Assumptions'!B51 -> 100 | C29: 7_Assumptions!B51
A30: Pilot cán bộ mục tiêu | B30: ='7_Assumptions'!B52 -> 3 | C30: 7_Assumptions!B52
A31: Pilot eval gate ngày | B31: ='7_Assumptions'!B53 -> 22/10/2026 | C31: 7_Assumptions!B53
A32: Procurement ngày | B32: ='7_Assumptions'!B54 -> 29/10/2026 | C32: 7_Assumptions!B54
A33: Pilot report ngày | B33: ='7_Assumptions'!B55 -> 06/12/2026 | C33: 7_Assumptions!B55
A34: 90 ngày kết thúc | B34: ='7_Assumptions'!B56 -> 06/01/2027 | C34: 7_Assumptions!B56
A35: Mục tiêu khách trả tiền | B35: ='7_Assumptions'!B59 -> 2 | C35: 7_Assumptions!B59
A36: Pain moment | B36: ='7_Assumptions'!B44 -> 08:30 sáng ngày làm việc | C36: 7_Assumptions!B44
A37: Gói cán bộ | B37: ='7_Assumptions'!B58 -> 3 | C37: 7_Assumptions!B58
A38: Pilot 4 tuần | B38: 4 tuần | C38: 5_90Day_Plan!C14
A39: 5 cán bộ + 2 IT | B39: 5 + 2 | C39: 5_90Day_Plan!B14
A40: QA base | B40: ='7_Assumptions'!B28 -> 0.05 | C40: 7_Assumptions!B28; sau gate
...
